Workbook

Sheet Suivi des candidatures
A1: Suivi des candidatures — PFE 2027
A2: Fatima Zahrae Chakib · PFE de 4 mois du 01/02/2027 au 31/05/2027 · Recherche du 29/10/2026 · Triées : offres ouvertes, puis priorité Haute, Moyenne et Basse · NP = non publié
A4: L'OFFRE | G4: MON CV | I4: CONTACT | N4: SUIVI | R4: PRÉ-EMBAUCHE | T4: ACTION
A5: Entreprise | B5: Secteur | C5: Ville | D5: Intitulé exact du poste / stage PFE | E5: Sujet de PFE proposé | F5: Compétences demandées | G5: CV | H5: Priorité | I5: Recruteur / contact RH | J5: E-mail vérifié | K5: Téléphone vérifié | L5: Lien offre / portail officiel | M5: Source (date) | N5: Statut | O5: Date d'envoi | P5: Date de relance | Q5: Date d'entretien | R5: Pré-embauche | S5: Conditions pré-embauche | T5: Prochaine action | U5: Offre ouverte ?
A6: Banque Populaire (BCP) | B6: Banque | C6: Casablanca + régions | D6: Stage PFE 2027 (Bac+5) H/F — candidatures spontanées, 4 à 6 mois | E6: Scoring de crédit PME par ML (XGBoost + SHAP) | F6: Bac+5 dernière année ; finance, risques, data, IA | G6: CV C | H6: 1 - Haute | I6: NP | J6: Via le portail | K6: NP | L6: Ouvrir ↗ | M6: Portail BCP ; Alwadifa (01/08/2026) | N6: À postuler | P6: =IF(O6="","",O6+10) | R6: Possible | S6: Non précisé : à demander | T6: Postuler sur le portail en ciblant « Risques » ou « Data » | U6: Oui
A7: Coface — DataLab | B7: Assurance-crédit / IA | C7: Casablanca | D7: Stages PFE 2026/2027 – DataLab (Pré-Embauche) | E7: Prédiction des défauts de paiement d'entreprises (ML + SHAP) | F7: Bac+5 ; ML supervisé et non supervisé, clustering, NLP, Python | G7: CV A | H7: 1 - Haute | I7: NP | J7: Via l'annonce | K7: NP | L7: Ouvrir ↗ | M7: Dreamjob (26/10/2026) ; Indeed | N7: À postuler | P7: =IF(O7="","",O7+10) | R7: Oui | S7: Annoncée « offre de pré-embauche » | T7: Postuler cette semaine ; ne pas citer le NLP sans l'avoir pratiqué | U7: Oui
A8: Forvis Mazars | B8: Audit | C8: Casablanca | D8: Stage de fin d'études — Auditeur financier (non sectoriel) — janvier 2027 | E8: Revue analytique automatisée des comptes (Python) | F8: Audit financier | G8: CV D | H8: 1 - Haute | I8: NP | J8: Via l'annonce | K8: NP | L8: Ouvrir ↗ | M8: Indeed / iAgora (10/2026) | N8: À postuler | P8: =IF(O8="","",O8+10) | R8: Possible | S8: Usuel en cabinet (non confirmé) | T8: Postuler et demander un démarrage au 01/02/2027 | U8: Oui
A9: Crédit du Maroc | B9: Banque | C9: Tanger / Tétouan | D9: Stage PFE – Analyste d'affaires | E9: Analyse des dossiers de crédit entreprises et du risque de contrepartie | F9: Bac+5 finance ; analyse financière, financements, risque de crédit | G9: CV C | H9: 1 - Haute | I9: NP | J9: Via le portail | K9: NP | L9: Ouvrir ↗ | M9: Portail officiel ; Alwadifa (11/2024) | N9: À vérifier | P9: =IF(O9="","",O9+10) | R9: Possible | T9: Une rare offre finance à Tanger : vérifier qu'elle est encore ouverte | U9: Non
A10: Crédit du Maroc | B10: Banque | C10: Plusieurs villes | D10: Campagne stagiaires PFE (Data & Business Analysis, Corporate Finance) | E10: Modèle de probabilité de défaut ; nouveau cadre de provisionnement 2027 | F10: Finance, data | G10: CV C | H10: 1 - Haute | I10: NP | J10: Via le portail | K10: NP | L10: Ouvrir ↗ | M10: Portail officiel (campagne 2025/2026) | N10: À vérifier | P10: =IF(O10="","",O10+10) | R10: Possible | T10: Surveiller la campagne 2026/2027 sur le portail | U10: Non
A11: KPMG Maroc | B11: Audit & conseil (risques) | C11: Casablanca | D11: Stage PFE — Consultant Risque Crédit (FRM) | E11: Modélisation et validation de modèles de risque de crédit | F11: Gestion des risques financiers | G11: CV C | H11: 1 - Haute | I11: NP | J11: Via le portail | K11: NP | L11: Ouvrir ↗ | M11: Portail KPMG Afrique (non daté) | N11: À vérifier | P11: =IF(O11="","",O11+10) | R11: Possible | T11: Très bonne adéquation avec ton credit scoring : vérifier l'offre | U11: Non
A12: Expleo Group | B12: Ingénierie / conseil | C12: Tanger | D12: Candidature directe — PFE FP&A / data finance | E12: Suite du modèle XGBoost : prévision des coûts et de la marge | F12: Python, XGBoost, FP&A, Power BI (acquis chez Expleo) | G12: CV A | H12: 1 - Haute | I12: NP | J12: NP | K12: NP | L12: Ouvrir ↗ | M12: Ton stage Expleo 2026 | N12: À contacter | P12: =IF(O12="","",O12+10) | R12: Possible | S12: À négocier avec ton ancien manager | T12: Écrire à ton ex-tuteur : proposer le sujet et demander une recommandation | U12: Non
A13: COFICAB Maroc | B13: Câbles automobile | C13: Tanger | D13: PFE Book : audit & contrôle de gestion, gestion financière (2025) | E13: Pilotage du BFR et reporting Power BI | F13: Audit, contrôle de gestion, finance | G13: CV B | H13: 1 - Haute | I13: NP | J13: Indiqué dans le PFE Book | K13: NP | L13: Ouvrir ↗ | M13: Bghit-nekhdem / PFE Book 2025 | N13: À vérifier | P13: =IF(O13="","",O13+10) | R13: Inconnue | T13: Guetter le PFE Book 2027 (le 2025 est sorti en décembre) | U13: Non
A14: TE Connectivity | B14: Automobile (connectique) | C14: Tanger | D14: Finance Development Program Trainee (m/f/d) — TNG-9000 | E14: Prévision des coûts de production et analyse des écarts | F14: Finance, génie industriel, audit, ERP, Excel | G14: CV B | H14: 1 - Haute | I14: NP | J14: NP | K14: NP | L14: Ouvrir ↗ | M14: careers.te.com (programme 09/2025) | N14: À vérifier | P14: =IF(O14="","",O14+10) | R14: Inconnue | S14: Programme trainee : débouché à vérifier | T14: Créer une alerte careers.te.com (Tanger, finance, intern) | U14: Non
A15: Renault Group | B15: Automobile | C15: Tanger (Melloussa) | D15: Contrôleur de Gestion – Performance & Contrôle – Stagiaires (H/F) | E15: Coût de revient usine prédictif + tableau de bord KPI | F15: Gestion, contrôle, data ; KPI, Power BI | G15: CV B | H15: 1 - Haute | I15: NP | J15: NP | K15: NP | L15: Ouvrir ↗ | M15: Dreamjob (13/02/2026) ; iAgora | N15: À vérifier | P15: =IF(O15="","",O15+10) | R15: Possible | S15: Graduate Program Casablanca & Tanger | T15: Campagne 2027 attendue vers février : postuler dès l'ouverture | U15: Non
A16: Tanger Med | B16: Port & logistique | C16: Tanger Med | D16: Candidature spontanée — PFE contrôle de gestion / analyse financière | E16: Prévision des volumes et revenus portuaires | F16: — | G16: CV B | H16: 1 - Haute | I16: NP | J16: NP | K16: NP | L16: Ouvrir ↗ | M16: Dreamjob | N16: À postuler | P16: =IF(O16="","",O16+10) | R16: Inconnue | T16: Déposer la candidature spontanée « Finance » | U16: Non
A17: Saham Bank | B17: Banque | C17: Casablanca | D17: Stagiaire PFE – Campagne 2026 – Finance / Audit / Commercial (50 postes) | E17: Pilotage de la rentabilité retail | F17: Bac+5 école d'ingénieurs ou de commerce | G17: CV B | H17: 1 - Haute | I17: NP | J17: NP | K17: NP | L17: Ouvrir ↗ | M17: Rekrute (janv.–avr. 2026) | N17: À vérifier | P17: =IF(O17="","",O17+10) | R17: Possible | T17: Surveiller la campagne 2027 (même période) | U17: Non
A18: Coface Maroc | B18: Assurance-crédit | C18: Casablanca | D18: Stage PFE — Analyse financière / risque crédit (6 mois, rémunéré) | E18: Grille de notation des acheteurs et alertes précoces | F18: Finance ; SAP, Excel ; risque client | G18: CV C | H18: 1 - Haute | I18: NP | J18: jobs@coface.com (annonce ~2024) | K18: NP | L18: Ouvrir ↗ | M18: Dreamjob (~2024) | N18: À contacter | P18: =IF(O18="","",O18+10) | R18: Possible | T18: Mail : préciser « analyse financière / risque crédit », 4 mois | U18: Non
A19: Deloitte Maroc | B19: Audit | C19: Casablanca | D19: Campagne stages Audit PFE (2026 ouverte en octobre 2025) | E19: Data analytics appliqué à l'audit | F19: Audit, comptabilité | G19: CV D | H19: 1 - Haute | I19: NP | J19: NP | K19: NP | L19: Ouvrir ↗ | M19: Dreamjob (10/2025) | N19: À vérifier | P19: =IF(O19="","",O19+10) | R19: Possible | T19: URGENT : la campagne 2027 devrait être ouverte, vérifier | U19: Non
A20: Renault Group | B20: Automobile — supply chain | C20: Tanger | D20: Stage Supply Chain — Data Analyst / Data Science (6 mois) | E20: Prévision de la demande et tableau de bord IA des achats | F20: Data, BI, Excel, Power BI | G20: CV A | H20: 2 - Moyenne | I20: NP | J20: NP | K20: NP | L20: Ouvrir ↗ | M20: iAgora (03–05/2026) | N20: À vérifier | P20: =IF(O20="","",O20+10) | R20: Possible | S20: Graduate Program | T20: Même campagne que le contrôle de gestion | U20: Non
A21: B Technologie | B21: Services / conseil | C21: Casablanca | D21: Stage PFE – Finance (H/F) – Power BI, 6 mois | E21: Industrialisation du reporting financier (Power BI) | F21: Finance, contrôle de gestion ou audit ; Power BI | G21: CV B | H21: 2 - Moyenne | I21: NP | J21: NP | K21: NP | L21: Ouvrir ↗ | M21: Jobsquare | N21: À vérifier | P21: =IF(O21="","",O21+10) | R21: Inconnue | T21: Vérifier la date et la durée (6 mois ou 4 ?) | U21: Non
A22: LabelVie (Carrefour) | B22: Grande distribution | C22: Skhirat (siège) | D22: Stagiaires PFE — Direction Finance | E22: Suivi budgétaire et contrôle des coûts | F22: Bac+5 finance / gestion | G22: CV B | H22: 2 - Moyenne | I22: NP | J22: NP | K22: NP | L22: Ouvrir ↗ | M22: Dreamjob (20/01/2026) | N22: À vérifier | P22: =IF(O22="","",O22+10) | R22: Inconnue | T22: Surveiller la campagne de janvier 2027 | U22: Non
A23: Valeo | B23: Équipementier automobile | C23: Tanger | D23: Stage Finance (H/F) | E23: Automatisation du reporting et prévision du BFR | F23: Non détaillées | G23: CV B | H23: 2 - Moyenne | I23: NP | J23: NP | K23: NP | L23: Ouvrir ↗ | M23: Indeed (non daté) | N23: À vérifier | P23: =IF(O23="","",O23+10) | R23: Inconnue | T23: Vérifier la date sur Indeed | U23: Non
A24: Orhan Automotive | B24: Équipementier automobile | C24: Tanger | D24: Stage Finance – Tanger | E24: Analyse des écarts budgétaires | F24: Non détaillées | G24: CV B | H24: 2 - Moyenne | I24: NP | J24: Dans l'annonce | K24: NP | L24: Ouvrir ↗ | M24: Dreamjob | N24: À vérifier | P24: =IF(O24="","",O24+10) | R24: Inconnue | T24: Relever l'e-mail et l'objet exigé | U24: Non
A25: APM Terminals MedPort | B25: Port & logistique | C25: Tanger Med | D25: Campagne Stages PFE (2025) | E25: Revenu par EVP et productivité du terminal | F25: Offres : HSSE, Opérations, Lean | G25: CV B | H25: 2 - Moyenne | I25: NP | J25: NP | K25: NP | L25: Ouvrir ↗ | M25: Dreamjob | N25: À vérifier | P25: =IF(O25="","",O25+10) | R25: Inconnue | T25: Chercher une offre finance ou Lean | U25: Non
A26: SCR (Société Centrale de Réassurance) | B26: Réassurance | C26: Casablanca | D26: Campagne de stages PFE 2025 (actuariat & modélisation des risques) | E26: Modélisation des risques de réassurance | F26: Actuariat, modélisation | G26: CV C | H26: 2 - Moyenne | I26: NP | J26: NP | K26: NP | L26: Ouvrir ↗ | M26: Rekrute (2025, close) | N26: À vérifier | P26: =IF(O26="","",O26+10) | R26: Inconnue | T26: Surveiller la campagne 2027 | U26: Non
A27: CIH Bank | B27: Banque | C27: Casablanca | D27: Candidature spontanée — PFE risk analytics | E27: Données de risque et algorithmes de scoring | F27: Recrute en CDI : Risk Analytics, Quant Risk | G27: CV C | H27: 2 - Moyenne | I27: NP | J27: NP | K27: NP | L27: Ouvrir ↗ | M27: Dreamjob | N27: À vérifier | P27: =IF(O27="","",O27+10) | R27: Inconnue | T27: Candidature spontanée « risques / data » | U27: Non
A28: Attijariwafa bank | B28: Banque | C28: Casablanca | D28: Candidature spontanée — PFE risques / finance | E28: Impact du provisionnement 2027 sur le coût du risque | F28: — | G28: CV C | H28: 2 - Moyenne | I28: NP | J28: NP | K28: NP | L28: Ouvrir ↗ | M28: Recherche web | N28: À vérifier | P28: =IF(O28="","",O28+10) | R28: Inconnue | T28: Vérifier le portail carrières | U28: Non
A29: AXA Assurance Maroc | B29: Assurance | C29: Casablanca | D29: Stagiaires études actuarielles (annonce 2022) | E29: Provisionnement des sinistres : Chain Ladder vs ML | F29: Actuariat, statistiques | G29: CV C | H29: 2 - Moyenne | I29: NP | J29: NP | K29: NP | L29: Ouvrir ↗ | M29: Dreamjob (2022) | N29: À vérifier | P29: =IF(O29="","",O29+10) | R29: Inconnue | T29: Candidature spontanée « actuariat / data » | U29: Non
A30: Wafa Assurance | B30: Assurance | C30: Casablanca | D30: Candidature spontanée — PFE actuariat / finance-data | E30: Tarification auto : GLM vs XGBoost | F30: Recrute : actuariat, IFRS 17, data (CDI) | G30: CV C | H30: 2 - Moyenne | I30: NP | J30: NP | K30: NP | L30: Ouvrir ↗ | M30: Dreamjob (13/10/2026) | N30: À vérifier | P30: =IF(O30="","",O30+10) | R30: Inconnue | T30: Candidature spontanée | U30: Non
A31: Sanlam Maroc | B31: Assurance | C31: Casablanca | D31: Campagne stagiaires PFE 2025 (finance, métiers de l'assurance) | E31: Rentabilité par branche et automatisation du reporting | F31: Finance ; convention de stage obligatoire | G31: CV C | H31: 2 - Moyenne | I31: NP | J31: recrutement@sanlam.ma (2023) | K31: NP | L31: Ouvrir ↗ | M31: Bghit-nekhdem (2025) | N31: À vérifier | P31: =IF(O31="","",O31+10) | R31: Inconnue | S31: Objet : Spécialité_Durée_Disponibilité | T31: Objet du mail : Finance_4_Février | U31: Non
A32: Allianz Maroc | B32: Assurance | C32: Casablanca | D32: Stage PFE — Actuariat Vie & Santé (2023–2024) | E32: Sinistralité santé et provisionnement | F32: Actuariat & finance | G32: CV C | H32: 2 - Moyenne | I32: NP | J32: recrutement.maroc@allianz.com (2023) | K32: NP | L32: Ouvrir ↗ | M32: Dreamjob (04/2023) | N32: À vérifier | P32: =IF(O32="","",O32+10) | R32: Inconnue | T32: Candidature spontanée par e-mail | U32: Non
A33: RMA | B33: Assurance | C33: Casablanca | D33: Candidature spontanée — PFE data | E33: Détection de fraude aux sinistres par ML | F33: Recrute : data analyst / scientist (CDI) | G33: CV A | H33: 2 - Moyenne | I33: NP | J33: NP | K33: NP | L33: Ouvrir ↗ | M33: Dreamjob | N33: À vérifier | P33: =IF(O33="","",O33+10) | R33: Inconnue | T33: Candidature spontanée | U33: Non
A34: KPMG Maroc | B34: Audit | C34: Casablanca | D34: Auditeur Moroccan Market — Stage PFE (F/H) | E34: Tests automatisés des journaux comptables | F34: Audit financier | G34: CV D | H34: 2 - Moyenne | I34: NP | J34: NP | K34: NP | L34: Ouvrir ↗ | M34: Portail KPMG | N34: À vérifier | P34: =IF(O34="","",O34+10) | R34: Possible | T34: Vérifier que l'offre est en ligne | U34: Non
A35: BDO Maroc | B35: Audit | C35: Plusieurs villes | D35: Stagiaires PFE en audit (11/2024) | E35: Revue analytique des comptes de PME | F35: Audit, comptabilité | G35: CV D | H35: 2 - Moyenne | I35: NP | J35: NP | K35: NP | L35: Ouvrir ↗ | M35: Dreamjob (11/2024) | N35: À vérifier | P35: =IF(O35="","",O35+10) | R35: Inconnue | T35: Demander s'il existe un bureau à Tanger | U35: Non
A36: Tanger Automotive City | B36: Zone industrielle | C36: Tanger | D36: Stage finance & comptabilité (Bac+2 à Bac+5) | E36: — | F36: Factures fournisseurs, rapprochements | G36: CV D | H36: 3 - Basse | I36: NP | J36: NP | K36: NP | L36: Ouvrir ↗ | M36: Modiami (10/2026) | N36: À vérifier | P36: =IF(O36="","",O36+10) | R36: Inconnue | T36: Plan B local (peu de data) | U36: Non
A37: OPmobility | B37: Équipementier automobile | C37: Tanger | D37: Candidature spontanée — PFE supply chain / data finance | E37: Prévision de la demande et impact sur le BFR | F37: — | G37: CV A | H37: 3 - Basse | I37: NP | J37: NP | K37: NP | L37: Ouvrir ↗ | M37: Indeed | N37: À vérifier | P37: =IF(O37="","",O37+10) | R37: Inconnue | T37: Surveiller Indeed | U37: Non
A38: TI Automotive | B38: Équipementier automobile | C38: Tanger | D38: Candidature spontanée — PFE data achats | E38: Tableau de bord de performance fournisseurs | F38: Stages publiés : achats, conception | G38: CV A | H38: 3 - Basse | I38: NP | J38: NP | K38: NP | L38: Ouvrir ↗ | M38: Dreamjob | N38: À vérifier | P38: =IF(O38="","",O38+10) | R38: Inconnue | U38: Non
A39: TRIGO Group | B39: Qualité automobile | C39: Tanger | D39: Candidature spontanée — PFE performance / data qualité | E39: Coûts de non-qualité | F39: Aucune offre trouvée | G39: CV A | H39: 3 - Basse | I39: NP | J39: NP | K39: NP | L39: Ouvrir ↗ | M39: Recherche web | N39: À vérifier | P39: =IF(O39="","",O39+10) | R39: Inconnue | U39: Non
A40: Yazaki Maroc | B40: Câblage automobile | C40: Tanger | D40: Candidature spontanée — PFE finance | E40: Rentabilité par projet client | F40: — | G40: CV B | H40: 3 - Basse | I40: NP | J40: NP | K40: NP | L40: Ouvrir ↗ | M40: Dreamjob | N40: À vérifier | P40: =IF(O40="","",O40+10) | R40: Inconnue | U40: Non
A41: Bank of Africa | B41: Banque | C41: Casablanca | D41: Candidature spontanée — PFE data / risque | E41: Modèles prédictifs pour les métiers | F41: Recrute : data scientist (5–10 ans) | G41: CV A | H41: 3 - Basse | I41: NP | J41: NP | K41: NP | L41: Ouvrir ↗ | M41: Bghit-nekhdem | N41: À vérifier | P41: =IF(O41="","",O41+10) | R41: Inconnue | U41: Non
...

Sheet Tableau de bord
A1: Tableau de bord — PFE 2027
A2: Mis à jour automatiquement depuis la feuille « Suivi des candidatures ». Rien à saisir ici, sauf l'objectif en jaune.
B4: Entreprises ciblées | E4: Offres PFE ouvertes vérifiées | H4: Candidatures envoyées | K4: Relances à faire
B5: =SUMPRODUCT(('Suivi des candidatures'!$A$6:$A$300<>"")/COUNTIF('Suivi des candidatures'!$A$6:$A$300,'Suivi des candidatures'!$A$6:$A$300&"")) -> 37 | E5: =COUNTIF('Suivi des candidatures'!$U$6:$U$300,"Oui") -> 3 | H5: =COUNTIF('Suivi des candidatures'!$N$6:$N$300,"Candidature envoyée")+COUNTIF('Suivi des candidatures'!$N$6:$N$300,"Relance à faire")+COUNTIF('Suivi des candidatures'!$N$6:$N$300,"Entretien prévu")+COUNTIF('Suivi des candidatures'!$N$6:$N$300,"En attente")+COUNTIF('Suivi des candidatures'!$N$6:$N$300,"Refus")+COUNTIF('Suivi des candidatures'!$N$6:$N$300,"Stage obtenu")+COUNTIF('Suivi des candidatures'!$N$6:$N$300,"Pré-embauche confirmée") -> 0 | K5: =COUNTIF('Suivi des candidatures'!$N$6:$N$300,"Relance à faire")+COUNTIFS('Suivi des candidatures'!$N$6:$N$300,"Candidature envoyée",'Suivi des candidatures'!$P$6:$P$300,"<="&TODAY())+COUNTIFS('Suivi des candidatures'!$N$6:$N$300,"En attente",'Suivi des candidatures'!$P$6:$P$300,"<="&TODAY()) -> 0
B8: Entretiens prévus | E8: Stages obtenus | H8: Pré-embauches confirmées | K8: Taux de réponse
B9: =COUNTIF('Suivi des candidatures'!$N$6:$N$300,"Entretien prévu") -> 0 | E9: =COUNTIF('Suivi des candidatures'!$N$6:$N$300,"Stage obtenu")+COUNTIF('Suivi des candidatures'!$N$6:$N$300,"Pré-embauche confirmée") -> 0 | H9: =COUNTIF('Suivi des candidatures'!$N$6:$N$300,"Pré-embauche confirmée") -> 0 | K9: =IFERROR((COUNTIF('Suivi des candidatures'!$N$6:$N$300,"Entretien prévu")+COUNTIF('Suivi des candidatures'!$N$6:$N$300,"Refus")+COUNTIF('Suivi des candidatures'!$N$6:$N$300,"Stage obtenu")+COUNTIF('Suivi des candidatures'!$N$6:$N$300,"Pré-embauche confirmée"))/H5,0) -> 0
B11: Taux de réponse = (entretiens + refus + stages + pré-embauches) ÷ candidatures envoyées. Relances = statut « Relance à faire » + envois dont la date de relance est atteinte.
B13: Objectif de candidatures | D13: 25 | E13: =IFERROR(MIN(H5/D13,1),0) -> 0
B15: TOP 10 — À FAIRE MAINTENANT
B16: Entreprise | D16: Action | J16: Quand | K16: Statut actuel (auto)
B17: 1. Banque Populaire | D17: Postuler au Stage PFE 2027 sur le portail (Risques ou Data) — CV C | J17: Cette semaine | K17: =IFERROR(INDEX('Suivi des candidatures'!$N$6:$N$300,MATCH(M17,'Suivi des candidatures'!$D$6:$D$300,0)),"—") -> À postuler | M17: Stage PFE 2027 (Bac+5) H/F — candidatures spontanées, 4 à 6 mois
B18: 2. Coface DataLab | D18: Postuler aux Stages PFE 2026/2027 (pré-embauche) — CV A | J18: Cette semaine | K18: =IFERROR(INDEX('Suivi des candidatures'!$N$6:$N$300,MATCH(M18,'Suivi des candidatures'!$D$6:$D$300,0)),"—") -> À postuler | M18: Stages PFE 2026/2027 – DataLab (Pré-Embauche)
B19: 3. Forvis Mazars | D19: Postuler (auditeur financier) et demander un démarrage le 01/02 — CV D | J19: Cette semaine | K19: =IFERROR(INDEX('Suivi des candidatures'!$N$6:$N$300,MATCH(M19,'Suivi des candidatures'!$D$6:$D$300,0)),"—") -> À postuler | M19: Stage de fin d'études — Auditeur financier (non sectoriel) — janvier 2027
B20: 4. Expleo | D20: Écrire à ton ex-tuteur : proposer un PFE sur la prévision | J20: Cette semaine | K20: =IFERROR(INDEX('Suivi des candidatures'!$N$6:$N$300,MATCH(M20,'Suivi des candidatures'!$D$6:$D$300,0)),"—") -> À contacter | M20: Candidature directe — PFE FP&A / data finance
B21: 5. Crédit du Maroc | D21: Vérifier l'offre « Analyste d'affaires Tanger/Tétouan » et postuler | J21: Semaine prochaine | K21: =IFERROR(INDEX('Suivi des candidatures'!$N$6:$N$300,MATCH(M21,'Suivi des candidatures'!$D$6:$D$300,0)),"—") -> À vérifier | M21: Stage PFE – Analyste d'affaires
B22: 6. KPMG | D22: Vérifier l'offre « Consultant Risque Crédit (FRM) » | J22: Semaine prochaine | K22: =IFERROR(INDEX('Suivi des candidatures'!$N$6:$N$300,MATCH(M22,'Suivi des candidatures'!$D$6:$D$300,0)),"—") -> À vérifier | M22: Stage PFE — Consultant Risque Crédit (FRM)
B23: 7. Deloitte | D23: Vérifier l'ouverture de la campagne audit PFE 2027 | J23: Semaine prochaine | K23: =IFERROR(INDEX('Suivi des candidatures'!$N$6:$N$300,MATCH(M23,'Suivi des candidatures'!$D$6:$D$300,0)),"—") -> À vérifier | M23: Campagne stages Audit PFE (2026 ouverte en octobre 2025)
B24: 8. Tanger Med | D24: Déposer une candidature spontanée « Finance » — CV B | J24: Novembre | K24: =IFERROR(INDEX('Suivi des candidatures'!$N$6:$N$300,MATCH(M24,'Suivi des candidatures'!$D$6:$D$300,0)),"—") -> À postuler | M24: Candidature spontanée — PFE contrôle de gestion / analyse financière
B25: 9. Coface Maroc | D25: Mail à jobs@coface.com : PFE analyse financière / risque crédit | J25: Novembre | K25: =IFERROR(INDEX('Suivi des candidatures'!$N$6:$N$300,MATCH(M25,'Suivi des candidatures'!$D$6:$D$300,0)),"—") -> À contacter | M25: Stage PFE — Analyse financière / risque crédit (6 mois, rémunéré)
B26: 10. Renault Tanger | D26: Créer une alerte : campagne PFE attendue vers février | J26: Janvier | K26: =IFERROR(INDEX('Suivi des candidatures'!$N$6:$N$300,MATCH(M26,'Suivi des candidatures'!$D$6:$D$300,0)),"—") -> À vérifier | M26: Contrôleur de Gestion – Performance & Contrôle – Stagiaires (H/F)
B29: Statut | C29: Nombre | H29: Version de CV | I29: Pistes | J29: Envoyées
B30: À vérifier | C30: =COUNTIF('Suivi des candidatures'!$N$6:$N$300,B30) -> 33 | H30: CV A | I30: =COUNTIF('Suivi des candidatures'!$G$6:$G$300,H30) -> 8 | J30: =COUNTIFS('Suivi des candidatures'!$G$6:$G$300,H30,'Suivi des candidatures'!$N$6:$N$300,"Candidature envoyée")+COUNTIFS('Suivi des candidatures'!$G$6:$G$300,H30,'Suivi des candidatures'!$N$6:$N$300,"Relance à faire")+COUNTIFS('Suivi des candidatures'!$G$6:$G$300,H30,'Suivi des candidatures'!$N$6:$N$300,"Entretien prévu")+COUNTIFS('Suivi des candidatures'!$G$6:$G$300,H30,'Suivi des candidatures'!$N$6:$N$300,"En attente")+COUNTIFS('Suivi des candidatures'!$G$6:$G$300,H30,'Suivi des candidatures'!$N$6:$N$300,"Refus")+COUNTIFS('Suivi des candidatures'!$G$6:$G$300,H30,'Suivi des candidatures'!$N$6:$N$300,"Stage obtenu")+COUNTIFS('Suivi des candidatures'!$G$6:$G$300,H30,'Suivi des candidatures'!$N$6:$N$300,"Pré-embauche confirmée") -> 0
B31: À contacter | C31: =COUNTIF('Suivi des candidatures'!$N$6:$N$300,B31) -> 3 | H31: CV B | I31: =COUNTIF('Suivi des candidatures'!$G$6:$G$300,H31) -> 11 | J31: =COUNTIFS('Suivi des candidatures'!$G$6:$G$300,H31,'Suivi des candidatures'!$N$6:$N$300,"Candidature envoyée")+COUNTIFS('Suivi des candidatures'!$G$6:$G$300,H31,'Suivi des candidatures'!$N$6:$N$300,"Relance à faire")+COUNTIFS('Suivi des candidatures'!$G$6:$G$300,H31,'Suivi des candidatures'!$N$6:$N$300,"Entretien prévu")+COUNTIFS('Suivi des candidatures'!$G$6:$G$300,H31,'Suivi des candidatures'!$N$6:$N$300,"En attente")+COUNTIFS('Suivi des candidatures'!$G$6:$G$300,H31,'Suivi des candidatures'!$N$6:$N$300,"Refus")+COUNTIFS('Suivi des candidatures'!$G$6:$G$300,H31,'Suivi des candidatures'!$N$6:$N$300,"Stage obtenu")+COUNTIFS('Suivi des candidatures'!$G$6:$G$300,H31,'Suivi des candidatures'!$N$6:$N$300,"Pré-embauche confirmée") -> 0
B32: À postuler | C32: =COUNTIF('Suivi des candidatures'!$N$6:$N$300,B32) -> 4 | H32: CV C | I32: =COUNTIF('Suivi des candidatures'!$G$6:$G$300,H32) -> 13 | J32: =COUNTIFS('Suivi des candidatures'!$G$6:$G$300,H32,'Suivi des candidatures'!$N$6:$N$300,"Candidature envoyée")+COUNTIFS('Suivi des candidatures'!$G$6:$G$300,H32,'Suivi des candidatures'!$N$6:$N$300,"Relance à faire")+COUNTIFS('Suivi des candidatures'!$G$6:$G$300,H32,'Suivi des candidatures'!$N$6:$N$300,"Entretien prévu")+COUNTIFS('Suivi des candidatures'!$G$6:$G$300,H32,'Suivi des candidatures'!$N$6:$N$300,"En attente")+COUNTIFS('Suivi des candidatures'!$G$6:$G$300,H32,'Suivi des candidatures'!$N$6:$N$300,"Refus")+COUNTIFS('Suivi des candidatures'!$G$6:$G$300,H32,'Suivi des candidatures'!$N$6:$N$300,"Stage obtenu")+COUNTIFS('Suivi des candidatures'!$G$6:$G$300,H32,'Suivi des candidatures'!$N$6:$N$300,"Pré-embauche confirmée") -> 0
B33: Candidature envoyée | C33: =COUNTIF('Suivi des candidatures'!$N$6:$N$300,B33) -> 0 | H33: CV D | I33: =COUNTIF('Suivi des candidatures'!$G$6:$G$300,H33) -> 8 | J33: =COUNTIFS('Suivi des candidatures'!$G$6:$G$300,H33,'Suivi des candidatures'!$N$6:$N$300,"Candidature envoyée")+COUNTIFS('Suivi des candidatures'!$G$6:$G$300,H33,'Suivi des candidatures'!$N$6:$N$300,"Relance à faire")+COUNTIFS('Suivi des candidatures'!$G$6:$G$300,H33,'Suivi des candidatures'!$N$6:$N$300,"Entretien prévu")+COUNTIFS('Suivi des candidatures'!$G$6:$G$300,H33,'Suivi des candidatures'!$N$6:$N$300,"En attente")+COUNTIFS('Suivi des candidatures'!$G$6:$G$300,H33,'Suivi des candidatures'!$N$6:$N$300,"Refus")+COUNTIFS('Suivi des candidatures'!$G$6:$G$300,H33,'Suivi des candidatures'!$N$6:$N$300,"Stage obtenu")+COUNTIFS('Suivi des candidatures'!$G$6:$G$300,H33,'Suivi des candidatures'!$N$6:$N$300,"Pré-embauche confirmée") -> 0
B34: Relance à faire | C34: =COUNTIF('Suivi des candidatures'!$N$6:$N$300,B34) -> 0
B35: Entretien prévu | C35: =COUNTIF('Suivi des candidatures'!$N$6:$N$300,B35) -> 0
B36: En attente | C36: =COUNTIF('Suivi des candidatures'!$N$6:$N$300,B36) -> 0
B37: Refus | C37: =COUNTIF('Suivi des candidatures'!$N$6:$N$300,B37) -> 0
B38: Stage obtenu | C38: =COUNTIF('Suivi des candidatures'!$N$6:$N$300,B38) -> 0
B39: Pré-embauche confirmée | C39: =COUNTIF('Suivi des candidatures'!$N$6:$N$300,B39) -> 0

Sheet Adaptation des CV
A1: Adaptation des CV — 4 versions
A2: Construit uniquement à partir de ton CV actuel. Aucune compétence ajoutée.
B4: CV A Data Science, IA & ML | C4: CV B Finance, FP&A & contrôle de gestion | D4: CV C Risque, assurance, crédit & actuariat | E4: CV D Audit, analyse financière & reporting
A5: Titre recommandé | B5: Élève ingénieure en génie financier — Data Science & IA appliquées à la finance | C5: Élève ingénieure en génie financier — FP&A & contrôle de gestion | D5: Élève ingénieure en génie financier (Actuariat & Finance) — Risque de crédit & modélisation | E5: Élève ingénieure en génie financier — Analyse financière, audit & reporting
A6: Compétences à mettre en avant | B6: • Python : pandas, scikit-learn, XGBoost, SHAP, PyMC • Machine learning, séries temporelles • Statistiques, R • Streamlit, Git/GitHub, pytest | C6: • FP&A, contrôle de gestion • Analyse des écarts budgétaires • Reporting, modélisation financière • Excel avancé, Power BI | D6: • Gestion des risques financiers • Credit scoring (ML) • Monte Carlo / LSMC, optimisation de portefeuille • Python, R, statistiques | E6: • Analyse financière (ratios, structure) • Comptabilité générale • Audit interne, contrôle interne • Excel avancé, Power BI
A7: Projets et expériences (dans cet ordre) | B7: 1. Expleo : prévision XGBoost (MAPE de 5,26 % à 2,39 %), SHAP, 33 tests 2. Credit scoring par ML 3. LSMC + PyPortfolioOpt | C7: 1. Expleo : tableau de bord Budget vs Réalisé, écarts, export Power BI 2. Montage financier (VAN, TRI, WACC, DSCR) 3. Analyse financière d'entreprises 4. Cabinet BRIMOU | D7: 1. Credit scoring par ML 2. Expleo : modèle prédictif + SHAP 3. LSMC + portefeuille 4. Montage financier : DSCR, stress tests 5. Certifications UIUC (Risk Management, RiskWise) | E7: 1. Cabinet BRIMOU : comptabilité, constitution de sociétés 2. Analyse financière d'entreprises 3. Expleo : reporting et écarts 4. DGI Tanger : dossiers fiscaux
A8: Mots-clés ATS | B8: machine learning, data science, Python, XGBoost, SHAP, prévision, séries temporelles, modèle prédictif, pipeline, Power BI, IA | C8: FP&A, contrôle de gestion, budget, forecast, Budget vs Réalisé, analyse des écarts, reporting, KPI, tableau de bord, Power BI, BFR | D8: risque de crédit, credit scoring, probabilité de défaut, modélisation, gestion des risques, actuariat, Monte Carlo, stress test, assurance | E8: audit, analyse financière, états financiers, ratios, comptabilité générale, contrôle interne, reporting financier, fiscalité
A9: À réduire ou reformuler | B9: Retirer la marque cosmétique, réduire la DGI à 1 ligne. Laisser l'anglais à « intermédiaire ». | C9: Réduire LSMC et PyMC. Présenter Expleo par ses résultats métier, pas par ses outils. | D9: Retirer la marque cosmétique. Ne pas citer IFRS 17 ni Solvabilité (absents de ton CV). | E9: Réduire le détail ML. Développer BRIMOU et la DGI en tâches concrètes.
A10: Cibles | B10: Coface DataLab, Expleo, RMA, Renault (data), Bank of Africa | C10: TE, Renault, COFICAB, Valeo, Tanger Med, Saham Bank, LabelVie, B Technologie | D10: BCP, Crédit du Maroc, KPMG (risque crédit), Coface, CIH, SCR, AXA, Wafa, Sanlam, Allianz | E10: Forvis Mazars, Deloitte, KPMG, BDO, EY, PwC
A12: À appliquer à toutes les versions
A13: • CV d'1 page. Nom de fichier : CV_FZ_Chakib_PFE2027_A.pdf (B, C ou D selon la version).
A14: • Sous le nom, ajouter : « Stage PFE 4 mois — 01/02/2027 → 31/05/2027 — ouverte à une pré-embauche ».
A15: • Chaque puce commence par un verbe d'action et donne un résultat chiffré.
A16: • Mettre le lien GitHub sur les CV A et C.

Sheet Contacts et liens utiles
A1: Contacts et liens utiles
A2: Seulement des coordonnées publiées. Aucun nom de recruteur n'est public : cherche « Talent Acquisition [entreprise] Maroc » sur LinkedIn.
A4: 1. E-MAILS PUBLIÉS (à reconfirmer avant envoi)
A5: Entreprise | B5: Type | C5: E-mail / adresse | D5: Fiabilité | E5: Source (date)
A6: Coface Maroc | B6: Candidature | C6: jobs@coface.com | D6: À reconfirmer | E6: Annonce PFE ~2024
A7: Allianz Maroc | B7: Candidature | C7: recrutement.maroc@allianz.com | D7: À reconfirmer | E7: Annonce 04/2023
A8: Sanlam Maroc | B8: Candidature | C8: recrutement@sanlam.ma | D8: À reconfirmer | E8: Annonce 06/2023
A9: Coface Maroc | B9: Adresse | C9: 225 bd d'Anfa, 20250 Casablanca | D9: Publiée | E9: Annonce DataLab
A11: 2. PORTAILS OFFICIELS
A12: Entreprise | B12: Type | C12: Remarque | D12: Lien | E12: Fiabilité
A13: Banque Populaire (BCP) | B13: Portail candidatures | C13: Stage PFE 2027 (Bac+5) | D13: Ouvrir ↗ | E13: Officiel
A14: Crédit du Maroc | B14: Portail carrières | C14: Offres PFE | D14: Ouvrir ↗ | E14: Officiel
A15: TE Connectivity | B15: Portail carrières | C15: Filtre Tanger | D15: Ouvrir ↗ | E15: Officiel
A16: KPMG Maroc | B16: Portail stages | C16: Stages & alternance Maroc | D16: Ouvrir ↗ | E16: Officiel
A17: Coface | B17: Offres Indeed | C17: DataLab, CDI data | D17: Ouvrir ↗ | E17: Plateforme
A18: Expleo | B18: Carrières | D18: Ouvrir ↗ | E18: À vérifier
A19: Renault Group | B19: Site officiel | C19: Rubrique Talents | D19: Ouvrir ↗ | E19: À vérifier
A20: Valeo | B20: Site officiel | C20: Carrières | D20: Ouvrir ↗ | E20: À vérifier
A21: Tanger Med | B21: Site officiel | C21: Carrières | D21: Ouvrir ↗ | E21: À vérifier
A22: Saham Bank | B22: Site officiel | C22: Carrières | D22: Ouvrir ↗ | E22: À vérifier
A23: Attijariwafa bank | B23: Site officiel | C23: Carrières | D23: Ouvrir ↗ | E23: À vérifier
A24: Wafa Assurance | B24: Site officiel | C24: Carrières | D24: Ouvrir ↗ | E24: À vérifier
A25: AXA Maroc | B25: Site officiel | C25: Carrières | D25: Ouvrir ↗ | E25: À vérifier
A26: RMA | B26: Site officiel | C26: Carrières | D26: Ouvrir ↗ | E26: À vérifier
A27: Forvis Mazars | B27: Site officiel | C27: Carrières Maroc | D27: Ouvrir ↗ | E27: À vérifier
A29: 3. PLATEFORMES D'OFFRES (créer des alertes « PFE » + finance / data / Tanger)
A30: Plateforme | B30: Type | C30: Conseil | D30: Lien
A31: ReKrute | B31: Emploi | C31: Alertes : stage PFE finance, data, actuariat | D31: Ouvrir ↗
A32: Indeed Maroc | B32: Emploi | C32: « stage PFE » Tanger et Casablanca | D32: Ouvrir ↗
A33: LinkedIn | B33: Réseau | C33: Alertes + messages aux RH | D33: Ouvrir ↗
A34: PFE Daba | B34: Agrégateur PFE | C34: Filtrer par ville et domaine | D34: Ouvrir ↗
A35: InteractJob | B35: Agrégateur | C35: Stages Maroc 2027 | D35: Ouvrir ↗
A36: Dreamjob.ma | B36: Agrégateur | C36: Rubrique Stages | D36: Ouvrir ↗
A37: iAgora | B37: Stages | C37: Offres Renault Tanger | D37: Ouvrir ↗
A38: Jobsquare | B38: Emploi | C38: Offres Tanger | D38: Ouvrir ↗
A40: 4. AGENCES D'ASSURANCE À TANGER (candidature spontanée, liste fournie par toi, non vérifiée)
A41: Agence | B41: Réseau | C41: Adresse
A42: Tanger Assurances Conseil | B42: RMA | C42: Place des Nations, 16 rue Antaki, Tanger
A43: Sanlam Assurance | B43: Sanlam | C43: 1, avenue Moulay Ismaïl, Tanger
A44: Bleu Assurances | B44: — | C44: Route de Rabat, Tanger
...

Sheet Sources
A1: Sources
A2: Recherche du 29/10/2026. Les agrégateurs relaient des offres : confirmer sur le site de l'entreprise.
A4: Banque Populaire (BCP) — Stage PFE 2027 (Bac+5) H/F — candidatures spontané | B4: https://bcp-cand.talent-soft.com/offre-de-emploi/emploi-candidatures-spontanees-stage-pfe-2027-bac-5-h-f_1672.aspx
A5: Coface — DataLab — Stages PFE 2026/2027 – DataLab (Pré-Embauche) | B5: https://ma.indeed.com/cmp/Coface/jobs
A6: Forvis Mazars — Stage de fin d'études — Auditeur financier (non se | B6: https://ma.indeed.com/Maroc-emplois-Stage-Finance
A7: Crédit du Maroc — Stage PFE – Analyste d'affaires | B7: https://carriere.creditdumaroc.ma/offre-de-emploi/emploi-stage-pfe-analyste-d-affaires-grand-casablanca-el-jadida-rabat-kenitra-temara-tanger-tetouan_3197.aspx
A8: Crédit du Maroc — Campagne stagiaires PFE (Data & Business Analysis, | B8: https://carriere.creditdumaroc.ma/Pages/Offre/detailoffre.aspx?LCID=1036&idOffre=3211&idOrigine=502&offerReference=2025-3211
A9: KPMG Maroc — Stage PFE — Consultant Risque Crédit (FRM) | B9: https://emplois-afrique.kpmg.com/stage-alternance-maroc
A10: Expleo Group — Candidature directe — PFE FP&A / data finance | B10: https://expleo.com/global/en/careers/
A11: COFICAB Maroc — PFE Book : audit & contrôle de gestion, gestion fi | B11: https://bghit-nekhdem.com/coficab-recrute-des-stagiaires-pfe-2025-decouvrez-les-projets-disponibles/
A12: TE Connectivity — Finance Development Program Trainee (m/f/d) — TNG- | B12: https://careers.te.com/job/Tanger-Finance-Development-Program-Trainee-%28mfd%29-TNG-9000/1259786700
A13: Renault Group — Contrôleur de Gestion – Performance & Contrôle – S | B13: https://www.iagora.com/work/fr/offre/stage-maroc-management/5984409
A14: Tanger Med — Candidature spontanée — PFE contrôle de gestion / | B14: https://www.dreamjob.ma/emploi/tanger-med-port-authority-candidature-spontanee/
A15: Saham Bank — Stagiaire PFE – Campagne 2026 – Finance / Audit / | B15: https://www.rekrute.com/offre-emploi-stagiaire-pfe---campagne-2026-hf---finance-audit---commercial-recrutement-saham-bank-casablanca-178707.html
... A48: Guide PFE Maroc — Jobsquare | B48: https://www.jobsquare.ma/blog/guide-stage-pfe-maroc/

Sheet Listes
A1: À vérifier | B1: 1 - Haute | C1: Oui | D1: CV A | E1: Oui
A2: À contacter | B2: 2 - Moyenne | C2: Possible | D2: CV B | E2: Non
A3: À postuler | B3: 3 - Basse | C3: Non | D3: CV C
A4: Candidature envoyée | C4: Inconnue | D4: CV D
A5: Relance à faire
A6: Entretien prévu
A7: En attente
A8: Refus
A9: Stage obtenu
A10: Pré-embauche confirmée
